2024-11-07 16:01:39.414461: I tensorflow/core/util/util.cc:169] oneDNN custom operations are on. You may see slightly different numerical results due to floating-point round-off errors from different computation orders. To turn them off, set the environment variable `TF_ENABLE_ONEDNN_OPTS=0`.
Couldn't connect to the Hub: (MaxRetryError("HTTPSConnectionPool(host='huggingface.co', port=443): Max retries exceeded with url: /api/models/CompVis/stable-diffusion-v1-4 (Caused by NewConnectionError('<urllib3.connection.HTTPSConnection object at 0x152c73fcf790>: Failed to establish a new connection: [Errno 101] Network is unreachable'))"), '(Request ID: 73accc01-c16b-455c-a7a8-f90282d3da4d)').
Will try to load from local cache.
Saving .png samples at /scratch/jp09/dd9648/LVMguidance/runs/exps/seed134/lvm_sd_negp_wkwn_skip5/images and .txt prompt at /scratch/jp09/dd9648/LVMguidance/runs/exps/seed134/lvm_sd_negp_wkwn_skip5/prompts
Saving final samples and text in /scratch/jp09/dd9648/LVMguidance/runs/exps/seed134/lvm_sd_negp_wkwn_skip5/reference
continue sampling
Already sampled 0
Total number of images that will be sampled: 30000
Loading pipeline components...:   0%|          | 0/7 [00:00<?, ?it/s]Loading pipeline components...:  43%|████▎     | 3/7 [00:00<00:00, 11.06it/s]Loading pipeline components...:  43%|████▎     | 3/7 [00:00<00:00,  8.54it/s]
Traceback (most recent call last):
  File "/home/562/dd9648/code/llm_guidance/vlm_sd_shard_neg_sk.py", line 343, in <module>
    main()
  File "/home/562/dd9648/code/llm_guidance/vlm_sd_shard_neg_sk.py", line 138, in main
    pipe = StableDiffusionLVMPipelineUpgradedNegPSkip.from_pretrained("CompVis/stable-diffusion-v1-4", device_map="balanced")
  File "/scratch/jp09/dd9648/sd22/lib/python3.9/site-packages/huggingface_hub/utils/_validators.py", line 114, in _inner_fn
    return fn(*args, **kwargs)
  File "/scratch/jp09/dd9648/sd22/lib/python3.9/site-packages/diffusers/pipelines/pipeline_utils.py", line 896, in from_pretrained
    loaded_sub_model = load_sub_model(
  File "/scratch/jp09/dd9648/sd22/lib/python3.9/site-packages/diffusers/pipelines/pipeline_loading_utils.py", line 704, in load_sub_model
    loaded_sub_model = load_method(os.path.join(cached_folder, name), **loading_kwargs)
  File "/scratch/jp09/dd9648/sd22/lib/python3.9/site-packages/huggingface_hub/utils/_validators.py", line 114, in _inner_fn
    return fn(*args, **kwargs)
  File "/scratch/jp09/dd9648/sd22/lib/python3.9/site-packages/diffusers/models/modeling_utils.py", line 886, in from_pretrained
    accelerate.load_checkpoint_and_dispatch(
TypeError: load_checkpoint_and_dispatch() got an unexpected keyword argument 'strict'
